Workbook

Sheet Dashboard
A1: AI Inventory Dashboard - NIST AI RMF View
A2: Generated from the AI Inventory. Includes AI RMF Profile coverage and distribution (P1-P20). Update the AI Inventory (Assigned Profile); all figures recalculate automatically.
A5: Total AI Systems | D5: Approved Systems | G5: Pending / Missing Evidence
A6: =COUNTA('AI Inventory'!$A$5:$A$11) -> 7 | D6: =COUNTIF('AI Inventory'!$R$5:$R$11,"Approved") -> 3 | G6: =COUNTIF('AI Inventory'!$R$5:$R$11,"Pending / Needs Documentation") -> 2
A8: High Risk Systems | D8: Critical Risk Systems | G8: Systems Processing PII
A9: =COUNTIF('AI Inventory'!$H$5:$H$11,"High") -> 4 | D9: =COUNTIF('AI Inventory'!$H$5:$H$11,"Critical") -> 0 | G9: =COUNTIF('AI Inventory'!$N$5:$N$11,"Yes") -> 2
A11: Confidential Data Systems | D11: Sensitive Data Systems | G11: Systems Processing IP
A12: =COUNTIF('AI Inventory'!$L$5:$L$11,"Confidential") -> 3 | D12: =COUNTIF('AI Inventory'!$L$5:$L$11,"Sensitive") -> 0 | G12: =COUNTIF('AI Inventory'!$M$5:$M$11,"Yes") -> 2
A14: Profiles Assigned | D14: Missing Profile | G14: Distinct Profiles In Use
A15: =COUNTIFS('AI Inventory'!$A$5:$A$11,"?*",'AI Inventory'!$T$5:$T$11,"P*") -> 7 | D15: =COUNTIFS('AI Inventory'!$A$5:$A$11,"?*",'AI Inventory'!$T$5:$T$11,"") -> 0 | G15: =SUMPRODUCT(--(COUNTIF('AI Inventory'!$T$5:$T$11,Profiles!$A$4:$A$23)>0)) -> 5
A17: Overall Critical/High Systems
A18: =COUNTIFS('Risk Assessment'!$A$4:$A$10,"?*",'Risk Assessment'!$F$4:$F$10,"High")+COUNTIFS('Risk Assessment'!$A$4:$A$10,"?*",'Risk Assessment'!$F$4:$F$10,"Critical") -> 5
A21: Systems by Assigned Profile
A22: Profile | B22: Name | C22: Count | E22: Profile | F22: Name | G22: Count
A23: P1 | B23: =INDEX(Profiles!$B$4:$B$23,MATCH(A23,Profiles!$A$4:$A$23,0)) -> Enterprise Productivity Assistant | C23: =COUNTIF('AI Inventory'!$T$5:$T$11,A23) -> 1 | E23: P11 | F23: =INDEX(Profiles!$B$4:$B$23,MATCH(E23,Profiles!$A$4:$A$23,0)) -> Finance and Reporting Support | G23: =COUNTIF('AI Inventory'!$T$5:$T$11,E23) -> 0
A24: P2 | B24: =INDEX(Profiles!$B$4:$B$23,MATCH(A24,Profiles!$A$4:$A$23,0)) -> Evaluation and Proof of Concept | C24: =COUNTIF('AI Inventory'!$T$5:$T$11,A24) -> 2 | E24: P12 | F24: =INDEX(Profiles!$B$4:$B$23,MATCH(E24,Profiles!$A$4:$A$23,0)) -> Security Operations Assistant | G24: =COUNTIF('AI Inventory'!$T$5:$T$11,E24) -> 0
A25: P3 | B25: =INDEX(Profiles!$B$4:$B$23,MATCH(A25,Profiles!$A$4:$A$23,0)) -> Domain and Technical Assistant | C25: =COUNTIF('AI Inventory'!$T$5:$T$11,A25) -> 1 | E25: P13 | F25: =INDEX(Profiles!$B$4:$B$23,MATCH(E25,Profiles!$A$4:$A$23,0)) -> Data Analytics and Business Intelligence | G25: =COUNTIF('AI Inventory'!$T$5:$T$11,E25) -> 0
A26: P4 | B26: =INDEX(Profiles!$B$4:$B$23,MATCH(A26,Profiles!$A$4:$A$23,0)) -> Developer and Code Assistant | C26: =COUNTIF('AI Inventory'!$T$5:$T$11,A26) -> 0 | E26: P14 | F26: =INDEX(Profiles!$B$4:$B$23,MATCH(E26,Profiles!$A$4:$A$23,0)) -> Marketing and Communications Content | G26: =COUNTIF('AI Inventory'!$T$5:$T$11,E26) -> 0
A27: P5 | B27: =INDEX(Profiles!$B$4:$B$23,MATCH(A27,Profiles!$A$4:$A$23,0)) -> Agentic Automation | C27: =COUNTIF('AI Inventory'!$T$5:$T$11,A27) -> 1 | E27: P15 | F27: =INDEX(Profiles!$B$4:$B$23,MATCH(E27,Profiles!$A$4:$A$23,0)) -> Procurement and Vendor Analysis | G27: =COUNTIF('AI Inventory'!$T$5:$T$11,E27) -> 0
A28: P6 | B28: =INDEX(Profiles!$B$4:$B$23,MATCH(A28,Profiles!$A$4:$A$23,0)) -> Customer or Supplier Facing | C28: =COUNTIF('AI Inventory'!$T$5:$T$11,A28) -> 0 | E28: P16 | F28: =INDEX(Profiles!$B$4:$B$23,MATCH(E28,Profiles!$A$4:$A$23,0)) -> Meeting Transcription and Summarization | G28: =COUNTIF('AI Inventory'!$T$5:$T$11,E28) -> 0
A29: P7 | B29: =INDEX(Profiles!$B$4:$B$23,MATCH(A29,Profiles!$A$4:$A$23,0)) -> People and HR Decision Support | C29: =COUNTIF('AI Inventory'!$T$5:$T$11,A29) -> 0 | E29: P17 | F29: =INDEX(Profiles!$B$4:$B$23,MATCH(E29,Profiles!$A$4:$A$23,0)) -> Training and Knowledge Assistant | G29: =COUNTIF('AI Inventory'!$T$5:$T$11,E29) -> 0
A30: P8 | B30: =INDEX(Profiles!$B$4:$B$23,MATCH(A30,Profiles!$A$4:$A$23,0)) -> Operational Technology and Laboratory | C30: =COUNTIF('AI Inventory'!$T$5:$T$11,A30) -> 0 | E30: P18 | F30: =INDEX(Profiles!$B$4:$B$23,MATCH(E30,Profiles!$A$4:$A$23,0)) -> Embedded AI Feature in Existing SaaS | G30: =COUNTIF('AI Inventory'!$T$5:$T$11,E30) -> 0
A31: P9 | B31: =INDEX(Profiles!$B$4:$B$23,MATCH(A31,Profiles!$A$4:$A$23,0)) -> Research and Formulation Support | C31: =COUNTIF('AI Inventory'!$T$5:$T$11,A31) -> 0 | E31: P19 | F31: =INDEX(Profiles!$B$4:$B$23,MATCH(E31,Profiles!$A$4:$A$23,0)) -> Synthetic Media Generation (Video & Audio) | G31: =COUNTIF('AI Inventory'!$T$5:$T$11,E31) -> 2
A32: P10 | B32: =INDEX(Profiles!$B$4:$B$23,MATCH(A32,Profiles!$A$4:$A$23,0)) -> Legal and Contract Analysis | C32: =COUNTIF('AI Inventory'!$T$5:$T$11,A32) -> 0 | E32: P20 | F32: =INDEX(Profiles!$B$4:$B$23,MATCH(E32,Profiles!$A$4:$A$23,0)) -> Identity Cloning & Impersonation (Voice or Likeness) | G32: =COUNTIF('AI Inventory'!$T$5:$T$11,E32) -> 0
A34: Executive Action Items
A35: Action | B35: Owner | C35: Priority | D35: Status
A36: Complete owner and approval evidence for Synthesia, Leverage AI, and Pictory.AI | B36: AI Governance / IT Security | C36: High | D36: Open
A37: Confirm Leverage AI agentic controls (least privilege, approval gate, vendor review) | B37: IT Security / Procurement | C37: High | D37: Open
A38: Verify licensing, AI-use disclosure, and no real-person cloning for Synthesia and Pictory.AI | B38: Communications / IT Security | C38: Medium | D38: Open
A39: Validate assigned AI RMF Profiles for all AI systems | B39: AI Governance / IT Security | C39: Medium | D39: Open
A40: Complete vendor security maturity review for U2C.AI before any production use of Inside Hazard Navigator | B40: IT Security / OT Security | C40: High | D40: Open
A41: Review tools where Overall Risk Rating is driven by Legal or Privacy rather than the base Risk Tier | B41: IT Security / Legal / Privacy | C41: Medium | D41: Open
A44: Risk Tier | B44: Count
A45: Low | B45: =COUNTIF('AI Inventory'!$H$5:$H$11,A45) -> 0
A46: Moderate | B46: =COUNTIF('AI Inventory'!$H$5:$H$11,A46) -> 3
A47: High | B47: =COUNTIF('AI Inventory'!$H$5:$H$11,A47) -> 4
A48: Critical | B48: =COUNTIF('AI Inventory'!$H$5:$H$11,A48) -> 0
A49: Overall Risk Rating = MAX(Validated Risk Tier, Vendor Risk Rating, Privacy Risk Rating, Legal Risk Rating). See Risk Assessment for the driving category per tool.
A50: Overall Risk Rating | B50: Count
A51: Low | B51: =COUNTIF('Risk Assessment'!$F$4:$F$10,A51) -> 0
...

Sheet AI Inventory
A1: AI Inventory - NIST AI RMF Aligned
A2: Source: user-provided inventory. Structure aligned to NIST AI RMF (Govern, Map, Measure, Manage). Assigned Profile is chosen using the Profile Selection sheet; Profile Selection Rule, Human Oversight, Profile Approval Authority, and Profile Review Frequency are looked up automatically from the Profiles sheet once a profile is assigned.
A3: Auto Updates - Do not edit this section
A4: AI ID | B4: Provider | C4: AI System Name | D4: Purpose | E4: Scope | F4: AI Capability | G4: Data Processed | H4: Risk Tier | I4: Profile Default Risk Tier | J4: Tier vs Profile Check | K4: Original Approved Data Classification | L4: Data Classification | M4: Intellectual Property Processed | N4: PII Processed | O4: Requested By | P4: Reviewed By | Q4: Approved Date | R4: Approval Status | S4: NIST AI RMF Function Coverage | T4: Assigned Profile | U4: Profile Selection Rule | V4: Human Oversight | W4: Profile Approval Authority | X4: Profile Review Frequency | Y4: Notes | Z4: Overall Risk Rating (reference)
A5: AI-001 | B5: Microsoft | C5: Copilot | D5: Productivity assistance and enterprise AI capability | E5: All employees | F5: Generative AI | G5: Organization Confidential | H5: =IF(OR(L5="Sensitive",N5="Yes"),"High",IF(OR(L5="Confidential",M5="Yes"),"High",IF(L5="Internal","Moderate","Low"))) -> High | I5: =IF(T5="","",INDEX(Profiles!$E$4:$E$23,MATCH(T5,Profiles!$A$4:$A$23,0))) -> High | J5: =IF(OR(H5="",T5=""),"",IF(ISNUMBER(SEARCH(H5,I5)),"Matches profile",IF(OR(H5="High",H5="Critical"),"Above profile (OK)","Review vs profile default"))) -> Matches profile | K5: Confidential | L5: Confidential | M5: Yes | N5: Yes | R5: Approved | S5: Govern | Map | Measure | Manage | T5: P1 | U5: =IFERROR(INDEX(Profiles!$K$4:$K$23,MATCH(T5,Profiles!$A$4:$A$23,0)),"") -> Rule 10 | V5: =IF(T5="","",INDEX(Profiles!$F$4:$F$23,MATCH(T5,Profiles!$A$4:$A$23,0))) -> Human-In-The-Loop for business decisions and external communication | W5: =IF(T5="","",INDEX(Profiles!$G$4:$G$23,MATCH(T5,Profiles!$A$4:$A$23,0))) -> ITGC | X5: =IF(T5="","",INDEX(Profiles!$J$4:$J$23,MATCH(T5,Profiles!$A$4:$A$23,0))) -> Semiannual | Y5: Capability is Embedded AI (activated inside Microsoft 365); profile remains P1 Enterprise Productivity Assistant. Confidential data, IP, and PII may be processed. | Z5: =IFERROR(INDEX('Risk Assessment'!$F$4:$F$10,MATCH(A5,'Risk Assessment'!$A$4:$A$10,0)),"") -> High
A6: AI-002 | B6: Anthropic | C6: Claude AI | D6: AI evaluation | E6: Limited PoC group | F6: Generative AI | G6: Custom made software code, uploaded documents, and data provided by user | H6: =IF(OR(L6="Sensitive",N6="Yes"),"High",IF(OR(L6="Confidential",M6="Yes"),"High",IF(L6="Internal","Moderate","Low"))) -> Moderate | I6: =IF(T6="","",INDEX(Profiles!$E$4:$E$23,MATCH(T6,Profiles!$A$4:$A$23,0))) -> Moderate | J6: =IF(OR(H6="",T6=""),"",IF(ISNUMBER(SEARCH(H6,I6)),"Matches profile",IF(OR(H6="High",H6="Critical"),"Above profile (OK)","Review vs profile default"))) -> Matches profile | K6: Internal Use | L6: Internal | M6: No | N6: No | R6: Approved with Conditions | S6: Govern | Map | Measure | Manage | T6: P2 | U6: =IFERROR(INDEX(Profiles!$K$4:$K$23,MATCH(T6,Profiles!$A$4:$A$23,0)),"") -> Rule 9 | V6: =IF(T6="","",INDEX(Profiles!$F$4:$F$23,MATCH(T6,Profiles!$A$4:$A$23,0))) -> Human-In-The-Loop | W6: =IF(T6="","",INDEX(Profiles!$G$4:$G$23,MATCH(T6,Profiles!$A$4:$A$23,0))) -> IT Security and Business Owner | X6: =IF(T6="","",INDEX(Profiles!$J$4:$J$23,MATCH(T6,Profiles!$A$4:$A$23,0))) -> At conclusion, or annually | Y6: Time-boxed PoC; Internal data only, no production dependency. | Z6: =IFERROR(INDEX('Risk Assessment'!$F$4:$F$10,MATCH(A6,'Risk Assessment'!$A$4:$A$10,0)),"") -> High
A7: AI-003 | B7: SomeGPT.ai | C7: JMP Learnbot | D7: AI used with UI interface bot | E7: Limited group with access to specific data | F7: Embedded AI | G7: Data and questions provided by the user specific to the navigation of the UI Pro tool | H7: =IF(OR(L7="Sensitive",N7="Yes"),"High",IF(OR(L7="Confidential",M7="Yes"),"High",IF(L7="Internal","Moderate","Low"))) -> Moderate | I7: =IF(T7="","",INDEX(Profiles!$E$4:$E$23,MATCH(T7,Profiles!$A$4:$A$23,0))) -> Moderate | J7: =IF(OR(H7="",T7=""),"",IF(ISNUMBER(SEARCH(H7,I7)),"Matches profile",IF(OR(H7="High",H7="Critical"),"Above profile (OK)","Review vs profile default"))) -> Matches profile | K7: Internal Use Only | L7: Internal | M7: No | N7: No | O7: [Contact-1]@organization.local | P7: IT Security and ITGC | Q7: 2026-06-04 00:00:00 | R7: Approved | S7: Govern | Map | Measure | Manage | T7: P3 | U7: =IFERROR(INDEX(Profiles!$K$4:$K$23,MATCH(T7,Profiles!$A$4:$A$23,0)),"") -> Rule 11 | V7: =IF(T7="","",INDEX(Profiles!$F$4:$F$23,MATCH(T7,Profiles!$A$4:$A$23,0))) -> Human-In-The-Loop | W7: =IF(T7="","",INDEX(Profiles!$G$4:$G$23,MATCH(T7,Profiles!$A$4:$A$23,0))) -> IT Security and Business Owner | X7: =IF(T7="","",INDEX(Profiles!$J$4:$J$23,MATCH(T7,Profiles!$A$4:$A$23,0))) -> Annual | Y7: Narrow group; JMP Pro navigation questions; Internal data only. | Z7: =IFERROR(INDEX('Risk Assessment'!$F$4:$F$10,MATCH(A7,'Risk Assessment'!$A$4:$A$10,0)),"") -> Moderate
A8: AI-004 | B8: Synthesia | C8: Synthesia | D8: All-in-one AI video platform to enhance training and communications; videos can be translated in 160+ languages | E8: HR, Operations; others may also use for his videos | F8: Generative AI | G8: Scripts and source material provided by the user; synthetic stock avatars and voices; generated video | H8: =IF(OR(L8="Sensitive",N8="Yes"),"High",IF(OR(L8="Confidential",M8="Yes"),"High",IF(L8="Internal","Moderate","Low"))) -> Moderate | I8: =IF(T8="","",INDEX(Profiles!$E$4:$E$23,MATCH(T8,Profiles!$A$4:$A$23,0))) -> High | J8: =IF(OR(H8="",T8=""),"",IF(ISNUMBER(SEARCH(H8,I8)),"Matches profile",IF(OR(H8="High",H8="Critical"),"Above profile (OK)","Review vs profile default"))) -> Review vs profile default | K8: Internal | L8: Internal | M8: No | N8: No | O8: [Contact-2]@organization.local | P8: IT Security | R8: Pending / Needs Documentation | S8: Govern | Map | Measure | Manage | T8: P19 | U8: =IFERROR(INDEX(Profiles!$K$4:$K$23,MATCH(T8,Profiles!$A$4:$A$23,0)),"") -> Rule 7 | V8: =IF(T8="","",INDEX(Profiles!$F$4:$F$23,MATCH(T8,Profiles!$A$4:$A$23,0))) -> Human-In-The-Loop with brand and legal review before publication | W8: =IF(T8="","",INDEX(Profiles!$G$4:$G$23,MATCH(T8,Profiles!$A$4:$A$23,0))) -> ITGC with Legal review (external-facing); IT Security and Business Owner (internal only) | X8: =IF(T8="","",INDEX(Profiles!$J$4:$J$23,MATCH(T8,Profiles!$A$4:$A$23,0))) -> Semiannual; Quarterly if external-facing | Y8: Human-driven GenAI video (synthetic/stock avatars) -> P19. Escalates to P20 only if a real organization person’s voice or likeness is cloned. | Z8: =IFERROR(INDEX('Risk Assessment'!$F$4:$F$10,MATCH(A8,'Risk Assessment'!$A$4:$A$10,0)),"") -> Moderate
A9: AI-005 | B9: Levy AI | C9: Levy AI | D9: Online platform for PO submission, confirmation, and updates; | E9: Customer Service and Commercial | F9: Agentic AI | G9: Purchase order data exchanged with customers and suppliers | H9: =IF(OR(L9="Sensitive",N9="Yes"),"High",IF(OR(L9="Confidential",M9="Yes"),"High",IF(L9="Internal","Moderate","Low"))) -> High | I9: =IF(T9="","",INDEX(Profiles!$E$4:$E$23,MATCH(T9,Profiles!$A$4:$A$23,0))) -> High to Critical | J9: =IF(OR(H9="",T9=""),"",IF(ISNUMBER(SEARCH(H9,I9)),"Matches profile",IF(OR(H9="High",H9="Critical"),"Above profile (OK)","Review vs profile default"))) -> Matches profile | K9: Confidential | L9: Confidential | M9: No | N9: Yes | O9: [Contact-3]@organization.local | P9: IT Security | R9: Pending / Needs Documentation | S9: Govern | Map | Measure | Manage | T9: P5 | U9: =IFERROR(INDEX(Profiles!$K$4:$K$23,MATCH(T9,Profiles!$A$4:$A$23,0)),"") -> Rule 4 | V9: =IF(T9="","",INDEX(Profiles!$F$4:$F$23,MATCH(T9,Profiles!$A$4:$A$23,0))) -> Human-In-The-Loop for privileged or irreversible actions | W9: =IF(T9="","",INDEX(Profiles!$G$4:$G$23,MATCH(T9,Profiles!$A$4:$A$23,0))) -> ITGC | X9: =IF(T9="","",INDEX(Profiles!$J$4:$J$23,MATCH(T9,Profiles!$A$4:$A$23,0))) -> Quarterly | Y9: Agentic PO workflow acting across systems -> P5. Customer/supplier-facing; confirm vendor controls and human approval gates for PO actions. | Z9: =IFERROR(INDEX('Risk Assessment'!$F$4:$F$10,MATCH(A9,'Risk Assessment'!$A$4:$A$10,0)),"") -> Critical
A10: AI-006 | B10: Startreck.AI | C10: Startreck.AI | D10: AI video generator for Company communications channels | E10: Communications | F10: Generative AI | G10: Scripts, documents, and media provided by the user; generated video | H10: =IF(OR(L10="Sensitive",N10="Yes"),"High",IF(OR(L10="Confidential",M10="Yes"),"High",IF(L10="Internal","Moderate","Low"))) -> High | I10: =IF(T10="","",INDEX(Profiles!$E$4:$E$23,MATCH(T10,Profiles!$A$4:$A$23,0))) -> High | J10: =IF(OR(H10="",T10=""),"",IF(ISNUMBER(SEARCH(H10,I10)),"Matches profile",IF(OR(H10="High",H10="Critical"),"Above profile (OK)","Review vs profile default"))) -> Matches profile | K10: Confidential | L10: Confidential | M10: No | N10: No | O10: [Contact-4]@organization.local | P10: IT Security and ITGC | R10: Rejected | S10: Govern | Map | Measure | Manage | T10: P19 | U10: =IFERROR(INDEX(Profiles!$K$4:$K$23,MATCH(T10,Profiles!$A$4:$A$23,0)),"") -> Rule 7 | V10: =IF(T10="","",INDEX(Profiles!$F$4:$F$23,MATCH(T10,Profiles!$A$4:$A$23,0))) -> Human-In-The-Loop with brand and legal review before publication | W10: =IF(T10="","",INDEX(Profiles!$G$4:$G$23,MATCH(T10,Profiles!$A$4:$A$23,0))) -> ITGC with Legal review (external-facing); IT Security and Business Owner (internal only) | X10: =IF(T10="","",INDEX(Profiles!$J$4:$J$23,MATCH(T10,Profiles!$A$4:$A$23,0))) -> Semiannual; Quarterly if external-facing | Y10: Human-driven GenAI video generation -> P19. Confirm licensing/rights and AI-use disclosure for external channels. | Z10: =IFERROR(INDEX('Risk Assessment'!$F$4:$F$10,MATCH(A10,'Risk Assessment'!$A$4:$A$10,0)),"") -> Critical
A11: AI-007 | B11: SAMPLE AI | C11: Potential Hazard Navigator | D11: To develop an AI tool used to query safety risk assessment data, MOC, and other process safety data - PILOT DEVELOPMENT ONLY | E11: Factory safety data | F11: AI APIs and Integrations | G11: System Diagrams or Documentation; Operational Procedures | H11: =IF(OR(L11="Sensitive",N11="Yes"),"High",IF(OR(L11="Confidential",M11="Yes"),"High",IF(L11="Internal","Moderate","Low"))) -> High | I11: =IF(T11="","",INDEX(Profiles!$E$4:$E$23,MATCH(T11,Profiles!$A$4:$A$23,0))) -> Moderate | J11: =IF(OR(H11="",T11=""),"",IF(ISNUMBER(SEARCH(H11,I11)),"Matches profile",IF(OR(H11="High",H11="Critical"),"Above profile (OK)","Review vs profile default"))) -> Above profile (OK) | K11: Confidential | L11: Internal | M11: Yes | N11: No | O11: [Contact-4]@organization.local | P11: IT | Q11: 2025-12-05 00:00:00 | R11: Approved | S11: Govern | Map | Measure | Manage | T11: P2 | U11: =IFERROR(INDEX(Profiles!$K$4:$K$23,MATCH(T11,Profiles!$A$4:$A$23,0)),"") -> Rule 9 | V11: =IF(T11="","",INDEX(Profiles!$F$4:$F$23,MATCH(T11,Profiles!$A$4:$A$23,0))) -> Human-In-The-Loop | W11: =IF(T11="","",INDEX(Profiles!$G$4:$G$23,MATCH(T11,Profiles!$A$4:$A$23,0))) -> IT Security and Business Owner | X11: =IF(T11="","",INDEX(Profiles!$J$4:$J$23,MATCH(T11,Profiles!$A$4:$A$23,0))) -> At conclusion, or annually | Y11: Time-boxed pilot querying EHS&S/process safety data; profile matches P2 default (Evaluation and Proof of Concept); risk tier validated above profile default given Confidential-adjacent safety data. | Z11: =IFERROR(INDEX('Risk Assessment'!$F$4:$F$10,MATCH(A11,'Risk Assessment'!$A$4:$A$10,0)),"") -> Critical

Sheet Profiles
A1: AI RMF Profiles - Reference (P1-P20)
A2: Assigned at intake (Step 1). Sets the starting position: default classification, default risk tier, oversight, controls. Final risk tier is confirmed in Step 2 and may be escalated but not silently downgraded. See the Profile Selection sheet for how to choose.
A3: Profile ID | B3: Profile Name | C3: Typical Use | D3: Default Classification | E3: Default Risk Tier | F3: Human Oversight | G3: Approval Authority | H3: Mandatory Controls | I3: Monitoring Focus | J3: Review Frequency | K3: Primary Selection Rule
A4: P1 | B4: Enterprise Productivity Assistant | C4: Broadly deployed assistant embedded in enterprise productivity tools | D4: Confidential | E4: High | F4: Human-In-The-Loop for business decisions and external communication | G4: ITGC | H4: Tenant data boundary; access aligned to existing permissions; audit logging; acceptable use guidance; user training | I4: Data exposure, oversharing, output reliance | J4: Semiannual | K4: Rule 10
A5: P2 | B5: Evaluation and Proof of Concept | C5: Time-boxed evaluation with a limited user group | D5: Internal | E5: Moderate | F5: Human-In-The-Loop | G5: IT Security and Business Owner | H5: Defined end date; named participants; Internal data only; no PII or Confidential data; no production dependency | I5: Scope and classification adherence | J5: At conclusion, or annually | K5: Rule 9
A6: P3 | B6: Domain and Technical Assistant | C6: Support for a specific tool, dataset, or technical discipline | D6: Internal | E6: Moderate | F6: Human-In-The-Loop | G6: IT Security and Business Owner | H6: Restricted user group; limited data scope; documented limitations; no automated decisions | I6: Scope creep, output accuracy | J6: Annual | K6: Rule 11
A7: P4 | B7: Developer and Code Assistant | C7: Code generation, review, and software development support | D7: Confidential | E7: High | F7: Human-In-The-Loop with code review | G7: ITGC | H7: No Sensitive data in prompts; code review before merge; secret scanning; license and IP review | I7: Source code exposure, insecure suggestions | J7: Semiannual | K7: Rule 7
A8: P5 | B8: Agentic Automation | C8: AI that executes multi-step tasks, calls tools, or acts on systems | D8: Confidential | E8: High to Critical | F8: Human-In-The-Loop for privileged or irreversible actions | G8: ITGC | H8: Least privilege identity; action allow list; approval gate for privileged actions; full action logging; rollback capability | I8: Action logs, privilege use, unexpected actions | J8: Quarterly | K8: Rule 4
A9: P6 | B9: Customer or Supplier Facing | C9: AI that interacts with external parties or generates external content | D9: Confidential | E9: High | F9: Human-In-The-Loop with approved response boundaries | G9: ITGC with Legal review | H9: Approved content boundaries; disclosure of AI use where required; escalation path to a human; brand and legal review | I9: Output accuracy, complaints, external disclosure | J9: Quarterly | K9: Rule 5
A10: P7 | B10: People and HR Decision Support | C10: AI supporting recruiting, evaluation, or workforce decisions | D10: Sensitive | E10: Critical | F10: Human-In-The-Loop with documented decision authority | G10: ITGC with Legal and Privacy review | H10: Documented human decision authority; bias assessment; privacy review; retention; notice where required | I10: Bias indicators, overrides, complaints | J10: Quarterly | K10: Rule 1
A11: P8 | B11: Operational Technology and Laboratory | C11: AI supporting plant, process, or laboratory activities | D11: Confidential to Sensitive | E11: Critical | F11: Human-In-The-Loop with no autonomous control actions | G11: ITGC with operational safety review | H11: Advisory only; no control system write access; network segmentation; engineering validation of outputs | I11: Output validation, attempted integrations, safety impact | J11: Quarterly | K11: Rule 3
A12: P9 | B12: Research and Formulation Support | C12: R&D support, scientific literature review, experimental design, formulation work | D12: Confidential to Sensitive | E12: High to Critical | F12: Human-In-The-Loop with technical validation of all outputs | G12: ITGC with R&D leadership review | H12: No unapproved upload of formulations or compositions; IP and export control review; technical validation before use; restricted user group | I12: Formulation and IP exposure, output accuracy, scope adherence | J12: Quarterly | K12: Rule 6
A13: P10 | B13: Legal and Contract Analysis | C13: Contract review, clause comparison, obligation extraction, legal research | D13: Confidential | E13: High | F13: Human-In-The-Loop with attorney or contract owner review | G13: ITGC with Legal review | H13: Privilege protection; no vendor training on submitted documents; retention limits; attorney or contract owner review of all conclusions | I13: Privileged content exposure, extraction accuracy | J13: Semiannual | K13: Rule 6
A14: P11 | B14: Finance and Reporting Support | C14: Financial data analysis, close support, reporting inputs | D14: Confidential | E14: High to Critical | F14: Human-In-The-Loop with reviewer independent of preparer | G14: ITGC with Finance and SOX review | H14: No autonomous journal or system postings; evidence retention for audit; segregation of duties; SOX control mapping where in scope | I14: Output accuracy, reliance within controls, audit evidence completeness | J14: Quarterly | K14: Rule 6
... A23: P20 | B23: Identity Cloning & Impersonation (Voice or Likeness) | C23: Cloned voice or likeness of a named real person, digital twins, custom personal avatars, in-voice dubbing | D23: Sensitive | E23: Critical | F23: Human-In-The-Loop with every output reviewed; no autonomous generation | G23: ITGC with Legal and Privacy review; documented consent of the individual on file | H23: Written, revocable consent from the person cloned held on file (for employees, decoupled from any condition of employment); biometric handling under GDPR and Illinois BIPA with a documented retention and destruction schedule; restricted, logged access to the cloned asset with revoke or delete on demand; AI-use disclosure or provenance watermark on output; prohibited uses defined (no approvals, financial, legal, or safety instructions issued via a cloned voice; anti-vishing safeguards); right-of-publicity review by Legal; defined incident path for misuse or deepfake | I23: Consent status and expiry, access to and use of the cloned asset, misuse or deepfake attempts, disclosure compliance, biometric retention compliance | J23: Quarterly | K23: Rule 2

Sheet Profile Selection
A1: AI RMF Profile Selection - Ordered Rules
A2: Apply the rules top to bottom and stop at the first match. Because the rules run highest-risk first, the sharper risk always wins — a tool that is both agentic and customer-facing is caught as agentic (Rule 4) before Rule 5. P20 (Rule 2) is always caught before P19 (Rule 7), and P18 (Rule 8) only applies when no earlier rule matched. If the use later changes so a different rule would apply, re-run selection — this is a Step 7 reassessment trigger.
A3: Rule | B3: If the intake record shows | C3: Source Intake Field | D3: Profile
A4: Rule 1 | B4: The system evaluates, ranks, screens, or prioritizes people | C4: Impact Assessment - People impact | D4: P7
A5: Rule 2 | B5: The system clones or replicates a real, identifiable person’s voice or likeness | C5: AI system type; Impact Assessment - People impact | D5: P20
A6: Rule 3 | B6: The system supports plant, PCN, process, or laboratory activity | C6: Impact Assessment - Safety impact | D6: P8
A7: Rule 4 | B7: The system acts on other systems, calls tools, or executes workflows | C7: AI system type - Agentic | D7: P5
A8: Rule 5 | B8: Output reaches customers, suppliers, or the public | C8: User scope; Impact Assessment - Stakeholders | D8: P6
A9: Rule 6 | B9: The tool is owned by a specialist function: R&D, Legal, Finance, Security Operations, Procurement, or Marketing | C9: Business Owner function | D9: P9, P10, P11, P12, P15, P14 respectively
A10: Rule 7 | B10: The tool is defined by a capability: code assistance, meeting capture, dataset querying, policy question answering, or video/audio generation | C10: Business use case and purpose | D10: P4, P16, P13, P17, P19 respectively
A11: Rule 8 | B11: AI is being enabled inside an application that is already approved | C11: Vendor and integration details | D11: P18
A12: Rule 9 | B12: The tool is a time-boxed pilot: Internal data only, no PII or Confidential data, and no production dependency | C12: User scope; Lifecycle = Pilot | D12: P2
A13: Rule 10 | B13: The tool is deployed enterprise-wide within the existing data boundary | C13: User scope - enterprise-wide | D13: P1
A14: Rule 11 | B14: The tool serves a narrow group, one tool or dataset, with no decision impact | C14: User scope and data scope | D14: P3
A15: Rule 12 | B15: No rule above matches | C15: Not applicable | D15: No profile; IT Security determines whether a new profile is warranted

Sheet Risk Assessment
A1: Risk Assessment - NIST AI RMF Govern, Map, Measure, Manage
A3: AI ID | B3: AI System Name | C3: Inherent Risk | D3: Validated Risk Tier (Impact & Control Validation) | E3: Validation Result | F3: Overall Risk Rating | G3: Risk Drivers | H3: Primary Risk Category | I3: Potential Harm | J3: Key Mitigations | K3: Risk Owner | L3: IT Risk Register Entry Required | M3: Risk Acceptance Required | N3: Assigned Profile | O3: Applicable Risk Categories | P3: Category Count | Q3: Applicable Harms | R3: Harm Count | S3: Required Evidence (from applicable categories)
A4: =INDEX('AI Inventory'!$A$5:$A$11,1) -> AI-001 | B4: =INDEX('AI Inventory'!$C$5:$C$11,1) -> Copilot | C4: =IFERROR(INDEX('AI Inventory'!$H$5:$H$11,MATCH(A4,'AI Inventory'!$A$5:$A$11,0)),"") -> High | D4: =INDEX('Reference Lists'!$B$4:$B$7,MAX(MATCH(C4,'Reference Lists'!$B$4:$B$7,0),MATCH( IF(INDEX('Risk & Harm Assessment'!$R$5:$R$11,MATCH($A4,'Risk & Harm Assessment'!$A$5:$A$11,0))="Yes","Critical", IF(AND(INDEX('Risk & Harm Assessment'!$H$5:$H$11,MATCH($A4,'Risk & Harm Assessment'!$A$5:$A$11,0))="Yes",ISNUMBER(SEARCH("Agentic",'AI Inventory'!F5))),"Critical", IF(AND(OR(INDEX('Risk & Harm Assessment'!$N$5:$N$11,MATCH($A4,'Risk & Harm Assessment'!$A$5:$A$11,0))="Yes",'AI Inventory'!N5="Yes"),'AI Inventory'!L5="Sensitive"),"Critical", IF(AND(OR(INDEX('Risk & Harm Assessment'!$N$5:$N$11,MATCH($A4,'Risk & Harm Assessment'!$A$5:$A$11,0))="Yes",'AI Inventory'!N5="Yes"),'AI Inventory'!L5="Confidential"),"High", IF(AND(ISNUMBER(SEARCH("Agentic",'AI Inventory'!F5)),INDEX('Risk & Harm Assessment'!$L$5:$L$11,MATCH($A4,'Risk & Harm Assessment'!$A$5:$A$11,0))="Yes"),"High", IF(AND(INDEX('Risk & Harm Assessment'!$K$5:$K$11,MATCH($A4,'Risk & Harm Assessment'!$A$5:$A$11,0))="Yes",'AI Inventory'!N5="Yes"),"High", IF(INDEX('Risk & Harm Assessment'!$I$5:$I$11,MATCH($A4,'Risk & Harm Assessment'!$A$5:$A$11,0))="Yes","High", IF(AND(ISNUMBER(SEARCH("Generative",'AI Inventory'!F5)),C4="Low"),"Moderate",C4) ))))))),'Reference Lists'!$B$4:$B$7,0))) -> High | E4: =IF(D4=C4,"Confirmed at "&C4,"Escalate: "&C4&" to "&D4) -> Confirmed at High | F4: =INDEX('Reference Lists'!$B$4:$B$7,MAX(MATCH(D4,'Reference Lists'!$B$4:$B$7,0),MATCH(INDEX('Vendor & Security'!$E$4:$E$10,MATCH($A4,'Vendor & Security'!$A$4:$A$10,0)),'Reference Lists'!$B$4:$B$7,0),MATCH(INDEX('Data & Privacy'!$D$4:$D$10,MATCH($A4,'Data & Privacy'!$A$4:$A$10,0)),'Reference Lists'!$B$4:$B$7,0),MATCH(INDEX('Legal & Compliance'!$D$4:$D$10,MATCH($A4,'Legal & Compliance'!$A$4:$A$10,0)),'Reference Lists'!$B$4:$B$7,0))) -> High | G4: =TRIM(_xlfn.TEXTJOIN(", ",TRUE,IF(MATCH(D4,'Reference Lists'!$B$4:$B$7,0)=MAX(MATCH(D4,'Reference Lists'!$B$4:$B$7,0),MATCH(INDEX('Vendor & Security'!$E$4:$E$10,MATCH($A4,'Vendor & Security'!$A$4:$A$10,0)),'Reference Lists'!$B$4:$B$7,0),MATCH(INDEX('Data & Privacy'!$D$4:$D$10,MATCH($A4,'Data & Privacy'!$A$4:$A$10,0)),'Reference Lists'!$B$4:$B$7,0),MATCH(INDEX('Legal & Compliance'!$D$4:$D$10,MATCH($A4,'Legal & Compliance'!$A$4:$A$10,0)),'Reference Lists'!$B$4:$B$7,0)),"Validated Risk ("&D4&")",""),IF(MATCH(INDEX('Vendor & Security'!$E$4:$E$10,MATCH($A4,'Vendor & Security'!$A$4:$A$10,0)),'Reference Lists'!$B$4:$B$7,0)=MAX(MATCH(D4,'Reference Lists'!$B$4:$B$7,0),MATCH(INDEX('Vendor & Security'!$E$4:$E$10,MATCH($A4,'Vendor & Security'!$A$4:$A$10,0)),'Reference Lists'!$B$4:$B$7,0),MATCH(INDEX('Data & Privacy'!$D$4:$D$10,MATCH($A4,'Data & Privacy'!$A$4:$A$10,0)),'Reference Lists'!$B$4:$B$7,0),MATCH(INDEX('Legal & Compliance'!$D$4:$D$10,MATCH($A4,'Legal & Compliance'!$A$4:$A$10,0)),'Reference Lists'!$B$4:$B$7,0)),"Vendor ("&INDEX('Vendor & Security'!$E$4:$E$10,MATCH($A4,'Vendor & Security'!$A$4:$A$10,0))&")",""),IF(MATCH(INDEX('Data & Privacy'!$D$4:$D$10,MATCH($A4,'Data & Privacy'!$A$4:$A$10,0)),'Reference Lists'!$B$4:$B$7,0)=MAX(MATCH(D4,'Reference Lists'!$B$4:$B$7,0),MATCH(INDEX('Vendor & Security'!$E$4:$E$10,MATCH($A4,'Vendor & Security'!$A$4:$A$10,0)),'Reference Lists'!$B$4:$B$7,0),MATCH(INDEX('Data & Privacy'!$D$4:$D$10,MATCH($A4,'Data & Privacy'!$A$4:$A$10,0)),'Reference Lists'!$B$4:$B$7,0),MATCH(INDEX('Legal & Compliance'!$D$4:$D$10,MATCH($A4,'Legal & Compliance'!$A$4:$A$10,0)),'Reference Lists'!$B$4:$B$7,0)),"Privacy ("&INDEX('Data & Privacy'!$D$4:$D$10,MATCH($A4,'Data & Privacy'!$A$4:$A$10,0))&")",""),IF(MATCH(INDEX('Legal & Compliance'!$D$4:$D$10,MATCH($A4,'Legal & Compliance'!$A$4:$A$10,0)),'Reference Lists'!$B$4:$B$7,0)=MAX(MATCH(D4,'Reference Lists'!$B$4:$B$7,0),MATCH(INDEX('Vendor & Security'!$E$4:$E$10,MATCH($A4,'Vendor & Security'!$A$4:$A$10,0)),'Reference Lists'!$B$4:$B$7,0),MATCH(INDEX('Data & Privacy'!$D$4:$D$10,MATCH($A4,'Data & Privacy'!$A$4:$A$10,0)),'Reference Lists'!$B$4:$B$7,0),MATCH(INDEX('Legal & Compliance'!$D$4:$D$10,MATCH($A4,'Legal & Compliance'!$A$4:$A$10,0)),'Reference Lists'!$B$4:$B$7,0)),"Legal ("&INDEX('Legal & Compliance'!$D$4:$D$10,MATCH($A4,'Legal & Compliance'!$A$4:$A$10,0))&")",""))) -> Validated Risk (High) | H4: Data leakage and disclosure | I4: Confidentiality harm | J4: Access controls, DLP, approved usage guidance, logging, vendor controls | K4: Business Owner / Requestor | L4: =IF(OR(D4="High",D4="Critical"),"Yes","No") -> Yes | M4: =IF(OR(D4="High",D4="Critical"),"Yes","No") -> Yes | N4: =IFERROR(INDEX('AI Inventory'!$T$5:$T$11,MATCH(A4,'AI Inventory'!$A$5:$A$11,0)),"") -> P1 | O4: =IFERROR(INDEX('Risk & Harm Assessment'!$W$5:$W$11,MATCH(A4,'Risk & Harm Assessment'!$A$5:$A$11,0)),"") -> Data leakage and disclosure, Prompt injection and adversarial input, Hallucination and incorrect output, Unauthorized data retention, Model drift and degradation, Overreliance and automation bias, Bias and harmful output, Third-party and value chain risk, Information security risk, Privacy risk, Regulatory and legal risk | P4: =IFERROR(INDEX('Risk & Harm Assessment'!$X$5:$X$11,MATCH(A4,'Risk & Harm Assessment'!$A$5:$A$11,0)),"") -> 11 | Q4: =IFERROR(INDEX('Risk & Harm Assessment'!$Y$5:$Y$11,MATCH(A4,'Risk & Harm Assessment'!$A$5:$A$11,0)),"") -> Individual harm, Organizational harm, Regulatory harm, Confidentiality harm, Information integrity harm | R4: =IFERROR(INDEX('Risk & Harm Assessment'!$Z$5:$Z$11,MATCH(A4,'Risk & Harm Assessment'!$A$5:$A$11,0)),"") -> 5 | S4: =_xlfn.TEXTJOIN(", ",TRUE,IF(INDEX('Risk & Harm Assessment'!$C$5:$C$11,MATCH($A4,'Risk & Harm Assessment'!$A$5:$A$11,0))="Yes",INDEX('Reference Lists'!$M$4:$M$16,1),""),IF(INDEX('Risk & Harm Assessment'!$D$5:$D$11,MATCH($A4,'Risk & Harm Assessment'!$A$5:$A$11,0))="Yes",INDEX('Reference Lists'!$M$4:$M$16,2),""),IF(INDEX('Risk & Harm Assessment'!$E$5:$E$11,MATCH($A4,'Risk & Harm Assessment'!$A$5:$A$11,0))="Yes",INDEX('Reference Lists'!$M$4:$M$16,3),""),IF(INDEX('Risk & Harm Assessment'!$F$5:$F$11,MATCH($A4,'Risk & Harm Assessment'!$A$5:$A$11,0))="Yes",INDEX('Reference Lists'!$M$4:$M$16,4),""),IF(INDEX('Risk & Harm Assessment'!$G$5:$G$11,MATCH($A4,'Risk & Harm Assessment'!$A$5:$A$11,0))="Yes",INDEX('Reference Lists'!$M$4:$M$16,5),""),IF(INDEX('Risk & Harm Assessment'!$H$5:$H$11,MATCH($A4,'Risk & Harm Assessment'!$A$5:$A$11,0))="Yes",INDEX('Reference Lists'!$M$4:$M$16,6),""),IF(INDEX('Risk & Harm Assessment'!$I$5:$I$11,MATCH($A4,'Risk & Harm Assessment'!$A$5:$A$11,0))="Yes",INDEX('Reference Lists'!$M$4:$M$16,7),""),IF(INDEX('Risk & Harm Assessment'!$J$5:$J$11,MATCH($A4,'Risk & Harm Assessment'!$A$5:$A$11,0))="Yes",INDEX('Reference Lists'!$M$4:$M$16,8),""),IF(INDEX('Risk & Harm Assessment'!$K$5:$K$11,MATCH($A4,'Risk & Harm Assessment'!$A$5:$A$11,0))="Yes",INDEX('Reference Lists'!$M$4:$M$16,9),""),IF(INDEX('Risk & Harm Assessment'!$L$5:$L$11,MATCH($A4,'Risk & Harm Assessment'!$A$5:$A$11,0))="Yes",INDEX('Reference Lists'!$M$4:$M$16,10),""),IF(INDEX('Risk & Harm Assessment'!$M$5:$M$11,MATCH($A4,'Risk & Harm Assessment'!$A$5:$A$11,0))="Yes",INDEX('Reference Lists'!$M$4:$M$16,11),""),IF(INDEX('Risk & Harm Assessment'!$N$5:$N$11,MATCH($A4,'Risk & Harm Assessment'!$A$5:$A$11,0))="Yes",INDEX('Reference Lists'!$M$4:$M$16,12),""),IF(INDEX('Risk & Harm Assessment'!$O$5:$O$11,MATCH($A4,'Risk & Harm Assessment'!$A$5:$A$11,0))="Yes",INDEX('Reference Lists'!$M$4:$M$16,13),"")) -> Data flow, classification, retention and deletion terms, Guardrails, abuse testing, monitoring, Validation process, user guidance, review requirements, Contract terms, DPA, vendor documentation, Change notification, monitoring approach, review cadence, Human oversight model, training, disclaimers, Bias assessment, human review, prohibited uses, ITDRA, SOC 2 or ISO evidence, subprocessor review, Architecture review, MFA, RBAC, logging, patching, Privacy review, DPA, retention controls, Legal and Compliance review, regulatory mapping
A5: =INDEX('AI Inventory'!$A$5:$A$11,2) -> AI-002 | B5: =INDEX('AI Inventory'!$C$5:$C$11,2) -> Claude AI | C5: =IFERROR(INDEX('AI Inventory'!$H$5:$H$11,MATCH(A5,'AI Inventory'!$A$5:$A$11,0)),"") -> Moderate | D5: =INDEX('Reference Lists'!$B$4:$B$7,MAX(MATCH(C5,'Reference Lists'!$B$4:$B$7,0),MATCH( IF(INDEX('Risk & Harm Assessment'!$R$5:$R$11,MATCH($A5,'Risk & Harm Assessment'!$A$5:$A$11,0))="Yes","Critical", IF(AND(INDEX('Risk & Harm Assessment'!$H$5:$H$11,MATCH($A5,'Risk & Harm Assessment'!$A$5:$A$11,0))="Yes",ISNUMBER(SEARCH("Agentic",'AI Inventory'!F6))),"Critical", IF(AND(OR(INDEX('Risk & Harm Assessment'!$N$5:$N$11,MATCH($A5,'Risk & Harm Assessment'!$A$5:$A$11,0))="Yes",'AI Inventory'!N6="Yes"),'AI Inventory'!L6="Sensitive"),"Critical", IF(AND(OR(INDEX('Risk & Harm Assessment'!$N$5:$N$11,MATCH($A5,'Risk & Harm Assessment'!$A$5:$A$11,0))="Yes",'AI Inventory'!N6="Yes"),'AI Inventory'!L6="Confidential"),"High", IF(AND(ISNUMBER(SEARCH("Agentic",'AI Inventory'!F6)),INDEX('Risk & Harm Assessment'!$L$5:$L$11,MATCH($A5,'Risk & Harm Assessment'!$A$5:$A$11,0))="Yes"),"High", IF(AND(INDEX('Risk & Harm Assessment'!$K$5:$K$11,MATCH($A5,'Risk & Harm Assessment'!$A$5:$A$11,0))="Yes",'AI Inventory'!N6="Yes"),"High", IF(INDEX('Risk & Harm Assessment'!$I$5:$I$11,MATCH($A5,'Risk & Harm Assessment'!$A$5:$A$11,0))="Yes","High", IF(AND(ISNUMBER(SEARCH("Generative",'AI Inventory'!F6)),C5="Low"),"Moderate",C5) ))))))),'Reference Lists'!$B$4:$B$7,0))) -> Moderate | E5: =IF(D5=C5,"Confirmed at "&C5,"Escalate: "&C5&" to "&D5) -> Confirmed at Moderate | F5: =INDEX('Reference Lists'!$B$4:$B$7,MAX(MATCH(D5,'Reference Lists'!$B$4:$B$7,0),MATCH(INDEX('Vendor & Security'!$E$4:$E$10,MATCH($A5,'Vendor & Security'!$A$4:$A$10,0)),'Reference Lists'!$B$4:$B$7,0),MATCH(INDEX('Data & Privacy'!$D$4:$D$10,MATCH($A5,'Data & Privacy'!$A$4:$A$10,0)),'Reference Lists'!$B$4:$B$7,0),MATCH(INDEX('Legal & Compliance'!$D$4:$D$10,MATCH($A5,'Legal & Compliance'!$A$4:$A$10,0)),'Reference Lists'!$B$4:$B$7,0))) -> High | G5: =TRIM(_xlfn.TEXTJOIN(", ",TRUE,IF(MATCH(D5,'Reference Lists'!$B$4:$B$7,0)=MAX(MATCH(D5,'Reference Lists'!$B$4:$B$7,0),MATCH(INDEX('Vendor & Security'!$E$4:$E$10,MATCH($A5,'Vendor & Security'!$A$4:$A$10,0)),'Reference Lists'!$B$4:$B$7,0),MATCH(INDEX('Data & Privacy'!$D$4:$D$10,MATCH($A5,'Data & Privacy'!$A$4:$A$10,0)),'Reference Lists'!$B$4:$B$7,0),MATCH(INDEX('Legal & Compliance'!$D$4:$D$10,MATCH($A5,'Legal & Compliance'!$A$4:$A$10,0)),'Reference Lists'!$B$4:$B$7,0)),"Validated Risk ("&D5&")",""),IF(MATCH(INDEX('Vendor & Security'!$E$4:$E$10,MATCH($A5,'Vendor & Security'!$A$4:$A$10,0)),'Reference Lists'!$B$4:$B$7,0)=MAX(MATCH(D5,'Reference Lists'!$B$4:$B$7,0),MATCH(INDEX('Vendor & Security'!$E$4:$E$10,MATCH($A5,'Vendor & Security'!$A$4:$A$10,0)),'Reference Lists'!$B$4:$B$7,0),MATCH(INDEX('Data & Privacy'!$D$4:$D$10,MATCH($A5,'Data & Privacy'!$A$4:$A$10,0)),'Reference Lists'!$B$4:$B$7,0),MATCH(INDEX('Legal & Compliance'!$D$4:$D$10,MATCH($A5,'Legal & Compliance'!$A$4:$A$10,0)),'Reference Lists'!$B$4:$B$7,0)),"Vendor ("&INDEX('Vendor & Security'!$E$4:$E$10,MATCH($A5,'Vendor & Security'!$A$4:$A$10,0))&")",""),IF(MATCH(INDEX('Data & Privacy'!$D$4:$D$10,MATCH($A5,'Data & Privacy'!$A$4:$A$10,0)),'Reference Lists'!$B$4:$B$7,0)=MAX(MATCH(D5,'Reference Lists'!$B$4:$B$7,0),MATCH(INDEX('Vendor & Security'!$E$4:$E$10,MATCH($A5,'Vendor & Security'!$A$4:$A$10,0)),'Reference Lists'!$B$4:$B$7,0),MATCH(INDEX('Data & Privacy'!$D$4:$D$10,MATCH($A5,'Data & Privacy'!$A$4:$A$10,0)),'Reference Lists'!$B$4:$B$7,0),MATCH(INDEX('Legal & Compliance'!$D$4:$D$10,MATCH($A5,'Legal & Compliance'!$A$4:$A$10,0)),'Reference Lists'!$B$4:$B$7,0)),"Privacy ("&INDEX('Data & Privacy'!$D$4:$D$10,MATCH($A5,'Data & Privacy'!$A$4:$A$10,0))&")",""),IF(MATCH(INDEX('Legal & Compliance'!$D$4:$D$10,MATCH($A5,'Legal & Compliance'!$A$4:$A$10,0)),'Reference Lists'!$B$4:$B$7,0)=MAX(MATCH(D5,'Reference Lists'!$B$4:$B$7,0),MATCH(INDEX('Vendor & Security'!$E$4:$E$10,MATCH($A5,'Vendor & Security'!$A$4:$A$10,0)),'Reference Lists'!$B$4:$B$7,0),MATCH(INDEX('Data & Privacy'!$D$4:$D$10,MATCH($A5,'Data & Privacy'!$A$4:$A$10,0)),'Reference Lists'!$B$4:$B$7,0),MATCH(INDEX('Legal & Compliance'!$D$4:$D$10,MATCH($A5,'Legal & Compliance'!$A$4:$A$10,0)),'Reference Lists'!$B$4:$B$7,0)),"Legal ("&INDEX('Legal & Compliance'!$D$4:$D$10,MATCH($A5,'Legal & Compliance'!$A$4:$A$10,0))&")",""))) -> Legal (High) | H5: Data leakage and disclosure | I5: Organizational harm | J5: Limited access, user guidance, vendor security review, retention limits, implement SSO | K5: Business Owner / Requestor | L5: =IF(OR(D5="High",D5="Critical"),"Yes","No") -> No | M5: =IF(OR(D5="High",D5="Critical"),"Yes","No") -> No | N5: =IFERROR(INDEX('AI Inventory'!$T$5:$T$11,MATCH(A5,'AI Inventory'!$A$5:$A$11,0)),"") -> P2 | O5: =IFERROR(INDEX('Risk & Harm Assessment'!$W$5:$W$11,MATCH(A5,'Risk & Harm Assessment'!$A$5:$A$11,0)),"") -> Data leakage and disclosure, Prompt injection and adversarial input, Hallucination and incorrect output, Unauthorized data retention, Model drift and degradation, Overreliance and automation bias, Bias and harmful output, Third-party and value chain risk, Information security risk | P5: =IFERROR(INDEX('Risk & Harm Assessment'!$X$5:$X$11,MATCH(A5,'Risk & Harm Assessment'!$A$5:$A$11,0)),"") -> 9 | Q5: =IFERROR(INDEX('Risk & Harm Assessment'!$Y$5:$Y$11,MATCH(A5,'Risk & Harm Assessment'!$A$5:$A$11,0)),"") -> Organizational harm, Confidentiality harm, Information integrity harm | R5: =IFERROR(INDEX('Risk & Harm Assessment'!$Z$5:$Z$11,MATCH(A5,'Risk & Harm Assessment'!$A$5:$A$11,0)),"") -> 3 | S5: =_xlfn.TEXTJOIN(", ",TRUE,IF(INDEX('Risk & Harm Assessment'!$C$5:$C$11,MATCH($A5,'Risk & Harm Assessment'!$A$5:$A$11,0))="Yes",INDEX('Reference Lists'!$M$4:$M$16,1),""),IF(INDEX('Risk & Harm Assessment'!$D$5:$D$11,MATCH($A5,'Risk & Harm Assessment'!$A$5:$A$11,0))="Yes",INDEX('Reference Lists'!$M$4:$M$16,2),""),IF(INDEX('Risk & Harm Assessment'!$E$5:$E$11,MATCH($A5,'Risk & Harm Assessment'!$A$5:$A$11,0))="Yes",INDEX('Reference Lists'!$M$4:$M$16,3),""),IF(INDEX('Risk & Harm Assessment'!$F$5:$F$11,MATCH($A5,'Risk & Harm Assessment'!$A$5:$A$11,0))="Yes",INDEX('Reference Lists'!$M$4:$M$16,4),""),IF(INDEX('Risk & Harm Assessment'!$G$5:$G$11,MATCH($A5,'Risk & Harm Assessment'!$A$5:$A$11,0))="Yes",INDEX('Reference Lists'!$M$4:$M$16,5),""),IF(INDEX('Risk & Harm Assessment'!$H$5:$H$11,MATCH($A5,'Risk & Harm Assessment'!$A$5:$A$11,0))="Yes",INDEX('Reference Lists'!$M$4:$M$16,6),""),IF(INDEX('Risk & Harm Assessment'!$I$5:$I$11,MATCH($A5,'Risk & Harm Assessment'!$A$5:$A$11,0))="Yes",INDEX('Reference Lists'!$M$4:$M$16,7),""),IF(INDEX('Risk & Harm Assessment'!$J$5:$J$11,MATCH($A5,'Risk & Harm Assessment'!$A$5:$A$11,0))="Yes",INDEX('Reference Lists'!$M$4:$M$16,8),""),IF(INDEX('Risk & Harm Assessment'!$K$5:$K$11,MATCH($A5,'Risk & Harm Assessment'!$A$5:$A$11,0))="Yes",INDEX('Reference Lists'!$M$4:$M$16,9),""),IF(INDEX('Risk & Harm Assessment'!$L$5:$L$11,MATCH($A5,'Risk & Harm Assessment'!$A$5:$A$11,0))="Yes",INDEX('Reference Lists'!$M$4:$M$16,10),""),IF(INDEX('Risk & Harm Assessment'!$M$5:$M$11,MATCH($A5,'Risk & Harm Assessment'!$A$5:$A$11,0))="Yes",INDEX('Reference Lists'!$M$4:$M$16,11),""),IF(INDEX('Risk & Harm Assessment'!$N$5:$N$11,MATCH($A5,'Risk & Harm Assessment'!$A$5:$A$11,0))="Yes",INDEX('Reference Lists'!$M$4:$M$16,12),""),IF(INDEX('Risk & Harm Assessment'!$O$5:$O$11,MATCH($A5,'Risk & Harm Assessment'!$A$5:$A$11,0))="Yes",INDEX('Reference Lists'!$M$4:$M$16,13),"")) -> Data flow, classification, retention and deletion terms, Guardrails, abuse testing, monitoring, Validation process, user guidance, review requirements, Contract terms, DPA, vendor documentation, Change notification, monitoring approach, review cadence, Human oversight model, training, disclaimers, Bias assessment, human review, prohibited uses, ITDRA, SOC 2 or ISO evidence, subprocessor review, Architecture review, MFA, RBAC, logging, patching
A6: =INDEX('AI Inventory'!$A$5:$A$11,3) -> AI-003 | B6: =INDEX('AI Inventory'!$C$5:$C$11,3) -> JMP Learnbot | C6: =IFERROR(INDEX('AI Inventory'!$H$5:$H$11,MATCH(A6,'AI Inventory'!$A$5:$A$11,0)),"") -> Moderate | D6: =INDEX('Reference Lists'!$B$4:$B$7,MAX(MATCH(C6,'Reference Lists'!$B$4:$B$7,0),MATCH( IF(INDEX('Risk & Harm Assessment'!$R$5:$R$11,MATCH($A6,'Risk & Harm Assessment'!$A$5:$A$11,0))="Yes","Critical", IF(AND(INDEX('Risk & Harm Assessment'!$H$5:$H$11,MATCH($A6,'Risk & Harm Assessment'!$A$5:$A$11,0))="Yes",ISNUMBER(SEARCH("Agentic",'AI Inventory'!F7))),"Critical", IF(AND(OR(INDEX('Risk & Harm Assessment'!$N$5:$N$11,MATCH($A6,'Risk & Harm Assessment'!$A$5:$A$11,0))="Yes",'AI Inventory'!N7="Yes"),'AI Inventory'!L7="Sensitive"),"Critical", IF(AND(OR(INDEX('Risk & Harm Assessment'!$N$5:$N$11,MATCH($A6,'Risk & Harm Assessment'!$A$5:$A$11,0))="Yes",'AI Inventory'!N7="Yes"),'AI Inventory'!L7="Confidential"),"High", IF(AND(ISNUMBER(SEARCH("Agentic",'AI Inventory'!F7)),INDEX('Risk & Harm Assessment'!$L$5:$L$11,MATCH($A6,'Risk & Harm Assessment'!$A$5:$A$11,0))="Yes"),"High", IF(AND(INDEX('Risk & Harm Assessment'!$K$5:$K$11,MATCH($A6,'Risk & Harm Assessment'!$A$5:$A$11,0))="Yes",'AI Inventory'!N7="Yes"),"High", IF(INDEX('Risk & Harm Assessment'!$I$5:$I$11,MATCH($A6,'Risk & Harm Assessment'!$A$5:$A$11,0))="Yes","High", IF(AND(ISNUMBER(SEARCH("Generative",'AI Inventory'!F7)),C6="Low"),"Moderate",C6) ))))))),'Reference Lists'!$B$4:$B$7,0))) -> Moderate | E6: =IF(D6=C6,"Confirmed at "&C6,"Escalate: "&C6&" to "&D6) -> Confirmed at Moderate | F6: =INDEX('Reference Lists'!$B$4:$B$7,MAX(MATCH(D6,'Reference Lists'!$B$4:$B$7,0),MATCH(INDEX('Vendor & Security'!$E$4:$E$10,MATCH($A6,'Vendor & Security'!$A$4:$A$10,0)),'Reference Lists'!$B$4:$B$7,0),MATCH(INDEX('Data & Privacy'!$D$4:$D$10,MATCH($A6,'Data & Privacy'!$A$4:$A$10,0)),'Reference Lists'!$B$4:$B$7,0),MATCH(INDEX('Legal & Compliance'!$D$4:$D$10,MATCH($A6,'Legal & Compliance'!$A$4:$A$10,0)),'Reference Lists'!$B$4:$B$7,0))) -> Moderate | G6: =TRIM(_xlfn.TEXTJOIN(", ",TRUE,IF(MATCH(D6,'Reference Lists'!$B$4:$B$7,0)=MAX(MATCH(D6,'Reference Lists'!$B$4:$B$7,0),MATCH(INDEX('Vendor & Security'!$E$4:$E$10,MATCH($A6,'Vendor & Security'!$A$4:$A$10,0)),'Reference Lists'!$B$4:$B$7,0),MATCH(INDEX('Data & Privacy'!$D$4:$D$10,MATCH($A6,'Data & Privacy'!$A$4:$A$10,0)),'Reference Lists'!$B$4:$B$7,0),MATCH(INDEX('Legal & Compliance'!$D$4:$D$10,MATCH($A6,'Legal & Compliance'!$A$4:$A$10,0)),'Reference Lists'!$B$4:$B$7,0)),"Validated Risk ("&D6&")",""),IF(MATCH(INDEX('Vendor & Security'!$E$4:$E$10,MATCH($A6,'Vendor & Security'!$A$4:$A$10,0)),'Reference Lists'!$B$4:$B$7,0)=MAX(MATCH(D6,'Reference Lists'!$B$4:$B$7,0),MATCH(INDEX('Vendor & Security'!$E$4:$E$10,MATCH($A6,'Vendor & Security'!$A$4:$A$10,0)),'Reference Lists'!$B$4:$B$7,0),MATCH(INDEX('Data & Privacy'!$D$4:$D$10,MATCH($A6,'Data & Privacy'!$A$4:$A$10,0)),'Reference Lists'!$B$4:$B$7,0),MATCH(INDEX('Legal & Compliance'!$D$4:$D$10,MATCH($A6,'Legal & Compliance'!$A$4:$A$10,0)),'Reference Lists'!$B$4:$B$7,0)),"Vendor ("&INDEX('Vendor & Security'!$E$4:$E$10,MATCH($A6,'Vendor & Security'!$A$4:$A$10,0))&")",""),IF(MATCH(INDEX('Data & Privacy'!$D$4:$D$10,MATCH($A6,'Data & Privacy'!$A$4:$A$10,0)),'Reference Lists'!$B$4:$B$7,0)=MAX(MATCH(D6,'Reference Lists'!$B$4:$B$7,0),MATCH(INDEX('Vendor & Security'!$E$4:$E$10,MATCH($A6,'Vendor & Security'!$A$4:$A$10,0)),'Reference Lists'!$B$4:$B$7,0),MATCH(INDEX('Data & Privacy'!$D$4:$D$10,MATCH($A6,'Data & Privacy'!$A$4:$A$10,0)),'Reference Lists'!$B$4:$B$7,0),MATCH(INDEX('Legal & Compliance'!$D$4:$D$10,MATCH($A6,'Legal & Compliance'!$A$4:$A$10,0)),'Reference Lists'!$B$4:$B$7,0)),"Privacy ("&INDEX('Data & Privacy'!$D$4:$D$10,MATCH($A6,'Data & Privacy'!$A$4:$A$10,0))&")",""),IF(MATCH(INDEX('Legal & Compliance'!$D$4:$D$10,MATCH($A6,'Legal & Compliance'!$A$4:$A$10,0)),'Reference Lists'!$B$4:$B$7,0)=MAX(MATCH(D6,'Reference Lists'!$B$4:$B$7,0),MATCH(INDEX('Vendor & Security'!$E$4:$E$10,MATCH($A6,'Vendor & Security'!$A$4:$A$10,0)),'Reference Lists'!$B$4:$B$7,0),MATCH(INDEX('Data & Privacy'!$D$4:$D$10,MATCH($A6,'Data & Privacy'!$A$4:$A$10,0)),'Reference Lists'!$B$4:$B$7,0),MATCH(INDEX('Legal & Compliance'!$D$4:$D$10,MATCH($A6,'Legal & Compliance'!$A$4:$A$10,0)),'Reference Lists'!$B$4:$B$7,0)),"Legal ("&INDEX('Legal & Compliance'!$D$4:$D$10,MATCH($A6,'Legal & Compliance'!$A$4:$A$10,0))&")",""))) -> Validated Risk (Moderate), Vendor (Moderate), Privacy (Moderate), Legal (Moderate) | H6: Data leakage and disclosure | I6: Confidentiality harm | J6: Limited access, user guidance, vendor security review | K6: Business Owner / Requestor | L6: =IF(OR(D6="High",D6="Critical"),"Yes","No") -> No | M6: =IF(OR(D6="High",D6="Critical"),"Yes","No") -> No | N6: =IFERROR(INDEX('AI Inventory'!$T$5:$T$11,MATCH(A6,'AI Inventory'!$A$5:$A$11,0)),"") -> P3 | O6: =IFERROR(INDEX('Risk & Harm Assessment'!$W$5:$W$11,MATCH(A6,'Risk & Harm Assessment'!$A$5:$A$11,0)),"") -> Data leakage and disclosure, Prompt injection and adversarial input, Hallucination and incorrect output, Unauthorized data retention, Model drift and degradation, Overreliance and automation bias, Third-party and value chain risk, Information security risk | P6: =IFERROR(INDEX('Risk & Harm Assessment'!$X$5:$X$11,MATCH(A6,'Risk & Harm Assessment'!$A$5:$A$11,0)),"") -> 8 | Q6: =IFERROR(INDEX('Risk & Harm Assessment'!$Y$5:$Y$11,MATCH(A6,'Risk & Harm Assessment'!$A$5:$A$11,0)),"") -> Organizational harm, Confidentiality harm, Information integrity harm | R6: =IFERROR(INDEX('Risk & Harm Assessment'!$Z$5:$Z$11,MATCH(A6,'Risk & Harm Assessment'!$A$5:$A$11,0)),"") -> 3 | S6: =_xlfn.TEXTJOIN(", ",TRUE,IF(INDEX('Risk & Harm Assessment'!$C$5:$C$11,MATCH($A6,'Risk & Harm Assessment'!$A$5:$A$11,0))="Yes",INDEX('Reference Lists'!$M$4:$M$16,1),""),IF(INDEX('Risk & Harm Assessment'!$D$5:$D$11,MATCH($A6,'Risk & Harm Assessment'!$A$5:$A$11,0))="Yes",INDEX('Reference Lists'!$M$4:$M$16,2),""),IF(INDEX('Risk & Harm Assessment'!$E$5:$E$11,MATCH($A6,'Risk & Harm Assessment'!$A$5:$A$11,0))="Yes",INDEX('Reference Lists'!$M$4:$M$16,3),""),IF(INDEX('Risk & Harm Assessment'!$F$5:$F$11,MATCH($A6,'Risk & Harm Assessment'!$A$5:$A$11,0))="Yes",INDEX('Reference Lists'!$M$4:$M$16,4),""),IF(INDEX('Risk & Harm Assessment'!$G$5:$G$11,MATCH($A6,'Risk & Harm Assessment'!$A$5:$A$11,0))="Yes",INDEX('Reference Lists'!$M$4:$M$16,5),""),IF(INDEX('Risk & Harm Assessment'!$H$5:$H$11,MATCH($A6,'Risk & Harm Assessment'!$A$5:$A$11,0))="Yes",INDEX('Reference Lists'!$M$4:$M$16,6),""),IF(INDEX('Risk & Harm Assessment'!$I$5:$I$11,MATCH($A6,'Risk & Harm Assessment'!$A$5:$A$11,0))="Yes",INDEX('Reference Lists'!$M$4:$M$16,7),""),IF(INDEX('Risk & Harm Assessment'!$J$5:$J$11,MATCH($A6,'Risk & Harm Assessment'!$A$5:$A$11,0))="Yes",INDEX('Reference Lists'!$M$4:$M$16,8),""),IF(INDEX('Risk & Harm Assessment'!$K$5:$K$11,MATCH($A6,'Risk & Harm Assessment'!$A$5:$A$11,0))="Yes",INDEX('Reference Lists'!$M$4:$M$16,9),""),IF(INDEX('Risk & Harm Assessment'!$L$5:$L$11,MATCH($A6,'Risk & Harm Assessment'!$A$5:$A$11,0))="Yes",INDEX('Reference Lists'!$M$4:$M$16,10),""),IF(INDEX('Risk & Harm Assessment'!$M$5:$M$11,MATCH($A6,'Risk & Harm Assessment'!$A$5:$A$11,0))="Yes",INDEX('Reference Lists'!$M$4:$M$16,11),""),IF(INDEX('Risk & Harm Assessment'!$N$5:$N$11,MATCH($A6,'Risk & Harm Assessment'!$A$5:$A$11,0))="Yes",INDEX('Reference Lists'!$M$4:$M$16,12),""),IF(INDEX('Risk & Harm Assessment'!$O$5:$O$11,MATCH($A6,'Risk & Harm Assessment'!$A$5:$A$11,0))="Yes",INDEX('Reference Lists'!$M$4:$M$16,13),"")) -> Data flow, classification, retention and deletion terms, Guardrails, abuse testing, monitoring, Validation process, user guidance, review requirements, Contract terms, DPA, vendor documentation, Change notification, monitoring approach, review cadence, Human oversight model, training, disclaimers, ITDRA, SOC 2 or ISO evidence, subprocessor review, Architecture review, MFA, RBAC, logging, patching
A7: =INDEX('AI Inventory'!$A$5:$A$11,4) -> AI-004 | B7: =INDEX('AI Inventory'!$C$5:$C$11,4) -> Synthesia | C7: =IFERROR(INDEX('AI Inventory'!$H$5:$H$11,MATCH(A7,'AI Inventory'!$A$5:$A$11,0)),"") -> Moderate | D7: =INDEX('Reference Lists'!$B$4:$B$7,MAX(MATCH(C7,'Reference Lists'!$B$4:$B$7,0),MATCH( IF(INDEX('Risk & Harm Assessment'!$R$5:$R$11,MATCH($A7,'Risk & Harm Assessment'!$A$5:$A$11,0))="Yes","Critical", IF(AND(INDEX('Risk & Harm Assessment'!$H$5:$H$11,MATCH($A7,'Risk & Harm Assessment'!$A$5:$A$11,0))="Yes",ISNUMBER(SEARCH("Agentic",'AI Inventory'!F8))),"Critical", IF(AND(OR(INDEX('Risk & Harm Assessment'!$N$5:$N$11,MATCH($A7,'Risk & Harm Assessment'!$A$5:$A$11,0))="Yes",'AI Inventory'!N8="Yes"),'AI Inventory'!L8="Sensitive"),"Critical", IF(AND(OR(INDEX('Risk & Harm Assessment'!$N$5:$N$11,MATCH($A7,'Risk & Harm Assessment'!$A$5:$A$11,0))="Yes",'AI Inventory'!N8="Yes"),'AI Inventory'!L8="Confidential"),"High", IF(AND(ISNUMBER(SEARCH("Agentic",'AI Inventory'!F8)),INDEX('Risk & Harm Assessment'!$L$5:$L$11,MATCH($A7,'Risk & Harm Assessment'!$A$5:$A$11,0))="Yes"),"High", IF(AND(INDEX('Risk & Harm Assessment'!$K$5:$K$11,MATCH($A7,'Risk & Harm Assessment'!$A$5:$A$11,0))="Yes",'AI Inventory'!N8="Yes"),"High", IF(INDEX('Risk & Harm Assessment'!$I$5:$I$11,MATCH($A7,'Risk & Harm Assessment'!$A$5:$A$11,0))="Yes","High", IF(AND(ISNUMBER(SEARCH("Generative",'AI Inventory'!F8)),C7="Low"),"Moderate",C7) ))))))),'Reference Lists'!$B$4:$B$7,0))) -> Moderate | E7: =IF(D7=C7,"Confirmed at "&C7,"Escalate: "&C7&" to "&D7) -> Confirmed at Moderate | F7: =INDEX('Reference Lists'!$B$4:$B$7,MAX(MATCH(D7,'Reference Lists'!$B$4:$B$7,0),MATCH(INDEX('Vendor & Security'!$E$4:$E$10,MATCH($A7,'Vendor & Security'!$A$4:$A$10,0)),'Reference Lists'!$B$4:$B$7,0),MATCH(INDEX('Data & Privacy'!$D$4:$D$10,MATCH($A7,'Data & Privacy'!$A$4:$A$10,0)),'Reference Lists'!$B$4:$B$7,0),MATCH(INDEX('Legal & Compliance'!$D$4:$D$10,MATCH($A7,'Legal & Compliance'!$A$4:$A$10,0)),'Reference Lists'!$B$4:$B$7,0))) -> Moderate | G7: =TRIM(_xlfn.TEXTJOIN(", ",TRUE,IF(MATCH(D7,'Reference Lists'!$B$4:$B$7,0)=MAX(MATCH(D7,'Reference Lists'!$B$4:$B$7,0),MATCH(INDEX('Vendor & Security'!$E$4:$E$10,MATCH($A7,'Vendor & Security'!$A$4:$A$10,0)),'Reference Lists'!$B$4:$B$7,0),MATCH(INDEX('Data & Privacy'!$D$4:$D$10,MATCH($A7,'Data & Privacy'!$A$4:$A$10,0)),'Reference Lists'!$B$4:$B$7,0),MATCH(INDEX('Legal & Compliance'!$D$4:$D$10,MATCH($A7,'Legal & Compliance'!$A$4:$A$10,0)),'Reference Lists'!$B$4:$B$7,0)),"Validated Risk ("&D7&")",""),IF(MATCH(INDEX('Vendor & Security'!$E$4:$E$10,MATCH($A7,'Vendor & Security'!$A$4:$A$10,0)),'Reference Lists'!$B$4:$B$7,0)=MAX(MATCH(D7,'Reference Lists'!$B$4:$B$7,0),MATCH(INDEX('Vendor & Security'!$E$4:$E$10,MATCH($A7,'Vendor & Security'!$A$4:$A$10,0)),'Reference Lists'!$B$4:$B$7,0),MATCH(INDEX('Data & Privacy'!$D$4:$D$10,MATCH($A7,'Data & Privacy'!$A$4:$A$10,0)),'Reference Lists'!$B$4:$B$7,0),MATCH(INDEX('Legal & Compliance'!$D$4:$D$10,MATCH($A7,'Legal & Compliance'!$A$4:$A$10,0)),'Reference Lists'!$B$4:$B$7,0)),"Vendor ("&INDEX('Vendor & Security'!$E$4:$E$10,MATCH($A7,'Vendor & Security'!$A$4:$A$10,0))&")",""),IF(MATCH(INDEX('Data & Privacy'!$D$4:$D$10,MATCH($A7,'Data & Privacy'!$A$4:$A$10,0)),'Reference Lists'!$B$4:$B$7,0)=MAX(MATCH(D7,'Reference Lists'!$B$4:$B$7,0),MATCH(INDEX('Vendor & Security'!$E$4:$E$10,MATCH($A7,'Vendor & Security'!$A$4:$A$10,0)),'Reference Lists'!$B$4:$B$7,0),MATCH(INDEX('Data & Privacy'!$D$4:$D$10,MATCH($A7,'Data & Privacy'!$A$4:$A$10,0)),'Reference Lists'!$B$4:$B$7,0),MATCH(INDEX('Legal & Compliance'!$D$4:$D$10,MATCH($A7,'Legal & Compliance'!$A$4:$A$10,0)),'Reference Lists'!$B$4:$B$7,0)),"Privacy ("&INDEX('Data & Privacy'!$D$4:$D$10,MATCH($A7,'Data & Privacy'!$A$4:$A$10,0))&")",""),IF(MATCH(INDEX('Legal & Compliance'!$D$4:$D$10,MATCH($A7,'Legal & Compliance'!$A$4:$A$10,0)),'Reference Lists'!$B$4:$B$7,0)=MAX(MATCH(D7,'Reference Lists'!$B$4:$B$7,0),MATCH(INDEX('Vendor & Security'!$E$4:$E$10,MATCH($A7,'Vendor & Security'!$A$4:$A$10,0)),'Reference Lists'!$B$4:$B$7,0),MATCH(INDEX('Data & Privacy'!$D$4:$D$10,MATCH($A7,'Data & Privacy'!$A$4:$A$10,0)),'Reference Lists'!$B$4:$B$7,0),MATCH(INDEX('Legal & Compliance'!$D$4:$D$10,MATCH($A7,'Legal & Compliance'!$A$4:$A$10,0)),'Reference Lists'!$B$4:$B$7,0)),"Legal ("&INDEX('Legal & Compliance'!$D$4:$D$10,MATCH($A7,'Legal & Compliance'!$A$4:$A$10,0))&")",""))) -> Validated Risk (Moderate), Privacy (Moderate), Legal (Moderate) | H7: Regulatory and legal risk | I7: Regulatory harm | J7: Licensing of avatars/voices, AI-use disclosure, brand/legal review, no real-person cloning (else P20), retention limits | K7: Business Owner / Requestor | L7: =IF(OR(D7="High",D7="Critical"),"Yes","No") -> No | M7: =IF(OR(D7="High",D7="Critical"),"Yes","No") -> No | N7: =IFERROR(INDEX('AI Inventory'!$T$5:$T$11,MATCH(A7,'AI Inventory'!$A$5:$A$11,0)),"") -> P19 | O7: =IFERROR(INDEX('Risk & Harm Assessment'!$W$5:$W$11,MATCH(A7,'Risk & Harm Assessment'!$A$5:$A$11,0)),"") -> Data leakage and disclosure, Hallucination and incorrect output, Unauthorized data retention, Overreliance and automation bias, Bias and harmful output, Third-party and value chain risk, Information security risk, Privacy risk, Regulatory and legal risk | P7: =IFERROR(INDEX('Risk & Harm Assessment'!$X$5:$X$11,MATCH(A7,'Risk & Harm Assessment'!$A$5:$A$11,0)),"") -> 9 | Q7: =IFERROR(INDEX('Risk & Harm Assessment'!$Y$5:$Y$11,MATCH(A7,'Risk & Harm Assessment'!$A$5:$A$11,0)),"") -> Individual harm, Organizational harm, Regulatory harm, Confidentiality harm, Information integrity harm | R7: =IFERROR(INDEX('Risk & Harm Assessment'!$Z$5:$Z$11,MATCH(A7,'Risk & Harm Assessment'!$A$5:$A$11,0)),"") -> 5 | S7: =_xlfn.TEXTJOIN(", ",TRUE,IF(INDEX('Risk & Harm Assessment'!$C$5:$C$11,MATCH($A7,'Risk & Harm Assessment'!$A$5:$A$11,0))="Yes",INDEX('Reference Lists'!$M$4:$M$16,1),""),IF(INDEX('Risk & Harm Assessment'!$D$5:$D$11,MATCH($A7,'Risk & Harm Assessment'!$A$5:$A$11,0))="Yes",INDEX('Reference Lists'!$M$4:$M$16,2),""),IF(INDEX('Risk & Harm Assessment'!$E$5:$E$11,MATCH($A7,'Risk & Harm Assessment'!$A$5:$A$11,0))="Yes",INDEX('Reference Lists'!$M$4:$M$16,3),""),IF(INDEX('Risk & Harm Assessment'!$F$5:$F$11,MATCH($A7,'Risk & Harm Assessment'!$A$5:$A$11,0))="Yes",INDEX('Reference Lists'!$M$4:$M$16,4),""),IF(INDEX('Risk & Harm Assessment'!$G$5:$G$11,MATCH($A7,'Risk & Harm Assessment'!$A$5:$A$11,0))="Yes",INDEX('Reference Lists'!$M$4:$M$16,5),""),IF(INDEX('Risk & Harm Assessment'!$H$5:$H$11,MATCH($A7,'Risk & Harm Assessment'!$A$5:$A$11,0))="Yes",INDEX('Reference Lists'!$M$4:$M$16,6),""),IF(INDEX('Risk & Harm Assessment'!$I$5:$I$11,MATCH($A7,'Risk & Harm Assessment'!$A$5:$A$11,0))="Yes",INDEX('Reference Lists'!$M$4:$M$16,7),""),IF(INDEX('Risk & Harm Assessment'!$J$5:$J$11,MATCH($A7,'Risk & Harm Assessment'!$A$5:$A$11,0))="Yes",INDEX('Reference Lists'!$M$4:$M$16,8),""),IF(INDEX('Risk & Harm Assessment'!$K$5:$K$11,MATCH($A7,'Risk & Harm Assessment'!$A$5:$A$11,0))="Yes",INDEX('Reference Lists'!$M$4:$M$16,9),""),IF(INDEX('Risk & Harm Assessment'!$L$5:$L$11,MATCH($A7,'Risk & Harm Assessment'!$A$5:$A$11,0))="Yes",INDEX('Reference Lists'!$M$4:$M$16,10),""),IF(INDEX('Risk & Harm Assessment'!$M$5:$M$11,MATCH($A7,'Risk & Harm Assessment'!$A$5:$A$11,0))="Yes",INDEX('Reference Lists'!$M$4:$M$16,11),""),IF(INDEX('Risk & Harm Assessment'!$N$5:$N$11,MATCH($A7,'Risk & Harm Assessment'!$A$5:$A$11,0))="Yes",INDEX('Reference Lists'!$M$4:$M$16,12),""),IF(INDEX('Risk & Harm Assessment'!$O$5:$O$11,MATCH($A7,'Risk & Harm Assessment'!$A$5:$A$11,0))="Yes",INDEX('Reference Lists'!$M$4:$M$16,13),"")) -> Data flow, classification, retention and deletion terms, Validation process, user guidance, review requirements, Contract terms, DPA, vendor documentation, Human oversight model, training, disclaimers, Bias assessment, human review, prohibited uses, ITDRA, SOC 2 or ISO evidence, subprocessor review, Architecture review, MFA, RBAC, logging, patching, Privacy review, DPA, retention controls, Legal and Compliance review, regulatory mapping
